2022-02-17 14:46:19,677 ERROR: Exception on /favicon.ico [GET] [in /Users/rjin/OneDrive/MyNotes/a.python/microblog/venv/lib/python3.10/site-packages/flask/app.py:1457]
Traceback (most recent call last):
  File "/Users/rjin/OneDrive/MyNotes/a.python/microblog/venv/lib/python3.10/site-packages/flask/app.py", line 2073, in wsgi_app
    response = self.full_dispatch_request()
  File "/Users/rjin/OneDrive/MyNotes/a.python/microblog/venv/lib/python3.10/site-packages/flask/app.py", line 1518, in full_dispatch_request
    rv = self.handle_user_exception(e)
  File "/Users/rjin/OneDrive/MyNotes/a.python/microblog/venv/lib/python3.10/site-packages/flask/app.py", line 1514, in full_dispatch_request
    rv = self.preprocess_request()
  File "/Users/rjin/OneDrive/MyNotes/a.python/microblog/venv/lib/python3.10/site-packages/flask/app.py", line 1857, in preprocess_request
    rv = self.ensure_sync(before_func)()
  File "/Users/rjin/OneDrive/MyNotes/a.python/microblog/app/main/routes.py", line 21, in before_request
    g.search_form = SearchForm()
  File "/Users/rjin/OneDrive/MyNotes/a.python/microblog/venv/lib/python3.10/site-packages/wtforms/form.py", line 208, in __call__
    return type.__call__(cls, *args, **kwargs)
  File "/Users/rjin/OneDrive/MyNotes/a.python/microblog/app/main/forms.py", line 54, in __init__
    kwargs['formdata'] = request.args
NameError: name 'request' is not defined
2022-02-17 14:46:20,069 ERROR: Exception on /index [GET] [in /Users/rjin/OneDrive/MyNotes/a.python/microblog/venv/lib/python3.10/site-packages/flask/app.py:1457]
Traceback (most recent call last):
  File "/Users/rjin/OneDrive/MyNotes/a.python/microblog/venv/lib/python3.10/site-packages/flask/app.py", line 2073, in wsgi_app
    response = self.full_dispatch_request()
  File "/Users/rjin/OneDrive/MyNotes/a.python/microblog/venv/lib/python3.10/site-packages/flask/app.py", line 1518, in full_dispatch_request
    rv = self.handle_user_exception(e)
  File "/Users/rjin/OneDrive/MyNotes/a.python/microblog/venv/lib/python3.10/site-packages/flask/app.py", line 1514, in full_dispatch_request
    rv = self.preprocess_request()
  File "/Users/rjin/OneDrive/MyNotes/a.python/microblog/venv/lib/python3.10/site-packages/flask/app.py", line 1857, in preprocess_request
    rv = self.ensure_sync(before_func)()
  File "/Users/rjin/OneDrive/MyNotes/a.python/microblog/app/main/routes.py", line 21, in before_request
    g.search_form = SearchForm()
  File "/Users/rjin/OneDrive/MyNotes/a.python/microblog/venv/lib/python3.10/site-packages/wtforms/form.py", line 208, in __call__
    return type.__call__(cls, *args, **kwargs)
  File "/Users/rjin/OneDrive/MyNotes/a.python/microblog/app/main/forms.py", line 54, in __init__
    kwargs['formdata'] = request.args
NameError: name 'request' is not defined
2022-02-17 14:46:20,142 ERROR: Exception on /favicon.ico [GET] [in /Users/rjin/OneDrive/MyNotes/a.python/microblog/venv/lib/python3.10/site-packages/flask/app.py:1457]
Traceback (most recent call last):
  File "/Users/rjin/OneDrive/MyNotes/a.python/microblog/venv/lib/python3.10/site-packages/flask/app.py", line 2073, in wsgi_app
    response = self.full_dispatch_request()
  File "/Users/rjin/OneDrive/MyNotes/a.python/microblog/venv/lib/python3.10/site-packages/flask/app.py", line 1518, in full_dispatch_request
    rv = self.handle_user_exception(e)
  File "/Users/rjin/OneDrive/MyNotes/a.python/microblog/venv/lib/python3.10/site-packages/flask/app.py", line 1514, in full_dispatch_request
    rv = self.preprocess_request()
  File "/Users/rjin/OneDrive/MyNotes/a.python/microblog/venv/lib/python3.10/site-packages/flask/app.py", line 1857, in preprocess_request
    rv = self.ensure_sync(before_func)()
  File "/Users/rjin/OneDrive/MyNotes/a.python/microblog/app/main/routes.py", line 21, in before_request
    g.search_form = SearchForm()
  File "/Users/rjin/OneDrive/MyNotes/a.python/microblog/venv/lib/python3.10/site-packages/wtforms/form.py", line 208, in __call__
    return type.__call__(cls, *args, **kwargs)
  File "/Users/rjin/OneDrive/MyNotes/a.python/microblog/app/main/forms.py", line 54, in __init__
    kwargs['formdata'] = request.args
NameError: name 'request' is not defined
2022-02-17 14:46:20,817 ERROR: Exception on /explore [GET] [in /Users/rjin/OneDrive/MyNotes/a.python/microblog/venv/lib/python3.10/site-packages/flask/app.py:1457]
Traceback (most recent call last):
  File "/Users/rjin/OneDrive/MyNotes/a.python/microblog/venv/lib/python3.10/site-packages/flask/app.py", line 2073, in wsgi_app
    response = self.full_dispatch_request()
  File "/Users/rjin/OneDrive/MyNotes/a.python/microblog/venv/lib/python3.10/site-packages/flask/app.py", line 1518, in full_dispatch_request
    rv = self.handle_user_exception(e)
  File "/Users/rjin/OneDrive/MyNotes/a.python/microblog/venv/lib/python3.10/site-packages/flask/app.py", line 1514, in full_dispatch_request
    rv = self.preprocess_request()
  File "/Users/rjin/OneDrive/MyNotes/a.python/microblog/venv/lib/python3.10/site-packages/flask/app.py", line 1857, in preprocess_request
    rv = self.ensure_sync(before_func)()
  File "/Users/rjin/OneDrive/MyNotes/a.python/microblog/app/main/routes.py", line 21, in before_request
    g.search_form = SearchForm()
  File "/Users/rjin/OneDrive/MyNotes/a.python/microblog/venv/lib/python3.10/site-packages/wtforms/form.py", line 208, in __call__
    return type.__call__(cls, *args, **kwargs)
  File "/Users/rjin/OneDrive/MyNotes/a.python/microblog/app/main/forms.py", line 54, in __init__
    kwargs['formdata'] = request.args
NameError: name 'request' is not defined
2022-02-17 14:46:20,926 ERROR: Exception on /favicon.ico [GET] [in /Users/rjin/OneDrive/MyNotes/a.python/microblog/venv/lib/python3.10/site-packages/flask/app.py:1457]
Traceback (most recent call last):
  File "/Users/rjin/OneDrive/MyNotes/a.python/microblog/venv/lib/python3.10/site-packages/flask/app.py", line 2073, in wsgi_app
    response = self.full_dispatch_request()
  File "/Users/rjin/OneDrive/MyNotes/a.python/microblog/venv/lib/python3.10/site-packages/flask/app.py", line 1518, in full_dispatch_request
    rv = self.handle_user_exception(e)
  File "/Users/rjin/OneDrive/MyNotes/a.python/microblog/venv/lib/python3.10/site-packages/flask/app.py", line 1514, in full_dispatch_request
    rv = self.preprocess_request()
  File "/Users/rjin/OneDrive/MyNotes/a.python/microblog/venv/lib/python3.10/site-packages/flask/app.py", line 1857, in preprocess_request
    rv = self.ensure_sync(before_func)()
  File "/Users/rjin/OneDrive/MyNotes/a.python/microblog/app/main/routes.py", line 21, in before_request
    g.search_form = SearchForm()
  File "/Users/rjin/OneDrive/MyNotes/a.python/microblog/venv/lib/python3.10/site-packages/wtforms/form.py", line 208, in __call__
    return type.__call__(cls, *args, **kwargs)
  File "/Users/rjin/OneDrive/MyNotes/a.python/microblog/app/main/forms.py", line 54, in __init__
    kwargs['formdata'] = request.args
NameError: name 'request' is not defined
2022-02-17 14:46:22,057 ERROR: Exception on /user/rjin [GET] [in /Users/rjin/OneDrive/MyNotes/a.python/microblog/venv/lib/python3.10/site-packages/flask/app.py:1457]
Traceback (most recent call last):
  File "/Users/rjin/OneDrive/MyNotes/a.python/microblog/venv/lib/python3.10/site-packages/flask/app.py", line 2073, in wsgi_app
    response = self.full_dispatch_request()
  File "/Users/rjin/OneDrive/MyNotes/a.python/microblog/venv/lib/python3.10/site-packages/flask/app.py", line 1518, in full_dispatch_request
    rv = self.handle_user_exception(e)
  File "/Users/rjin/OneDrive/MyNotes/a.python/microblog/venv/lib/python3.10/site-packages/flask/app.py", line 1514, in full_dispatch_request
    rv = self.preprocess_request()
  File "/Users/rjin/OneDrive/MyNotes/a.python/microblog/venv/lib/python3.10/site-packages/flask/app.py", line 1857, in preprocess_request
    rv = self.ensure_sync(before_func)()
  File "/Users/rjin/OneDrive/MyNotes/a.python/microblog/app/main/routes.py", line 21, in before_request
    g.search_form = SearchForm()
  File "/Users/rjin/OneDrive/MyNotes/a.python/microblog/venv/lib/python3.10/site-packages/wtforms/form.py", line 208, in __call__
    return type.__call__(cls, *args, **kwargs)
  File "/Users/rjin/OneDrive/MyNotes/a.python/microblog/app/main/forms.py", line 54, in __init__
    kwargs['formdata'] = request.args
NameError: name 'request' is not defined
2022-02-17 14:46:22,127 ERROR: Exception on /favicon.ico [GET] [in /Users/rjin/OneDrive/MyNotes/a.python/microblog/venv/lib/python3.10/site-packages/flask/app.py:1457]
Traceback (most recent call last):
  File "/Users/rjin/OneDrive/MyNotes/a.python/microblog/venv/lib/python3.10/site-packages/flask/app.py", line 2073, in wsgi_app
    response = self.full_dispatch_request()
  File "/Users/rjin/OneDrive/MyNotes/a.python/microblog/venv/lib/python3.10/site-packages/flask/app.py", line 1518, in full_dispatch_request
    rv = self.handle_user_exception(e)
  File "/Users/rjin/OneDrive/MyNotes/a.python/microblog/venv/lib/python3.10/site-packages/flask/app.py", line 1514, in full_dispatch_request
    rv = self.preprocess_request()
  File "/Users/rjin/OneDrive/MyNotes/a.python/microblog/venv/lib/python3.10/site-packages/flask/app.py", line 1857, in preprocess_request
    rv = self.ensure_sync(before_func)()
  File "/Users/rjin/OneDrive/MyNotes/a.python/microblog/app/main/routes.py", line 21, in before_request
    g.search_form = SearchForm()
  File "/Users/rjin/OneDrive/MyNotes/a.python/microblog/venv/lib/python3.10/site-packages/wtforms/form.py", line 208, in __call__
    return type.__call__(cls, *args, **kwargs)
  File "/Users/rjin/OneDrive/MyNotes/a.python/microblog/app/main/forms.py", line 54, in __init__
    kwargs['formdata'] = request.args
NameError: name 'request' is not defined
2022-02-17 14:47:28,748 INFO: Microblog startup [in /Users/rjin/OneDrive/MyNotes/a.python/microblog/app/__init__.py:84]
2022-02-17 14:50:25,572 INFO: Microblog startup [in /Users/rjin/OneDrive/MyNotes/a.python/microblog/app/__init__.py:84]
