2022-01-19 10:59:17,063 INFO: Microblog startup [in /Users/rjin/OneDrive/MyNotes/a.python/microblog/app/__init__.py:33]
2022-01-19 11:00:19,112 ERROR: Exception on /edit_profile [POST] [in /Users/rjin/OneDrive/MyNotes/a.python/microblog/venv/lib/python3.10/site-packages/flask/app.py:1457]
Traceback (most recent call last):
  File "/Users/rjin/OneDrive/MyNotes/a.python/microblog/venv/lib/python3.10/site-packages/sqlalchemy/engine/base.py", line 1802, in _execute_context
    self.dialect.do_execute(
  File "/Users/rjin/OneDrive/MyNotes/a.python/microblog/venv/lib/python3.10/site-packages/sqlalchemy/engine/default.py", line 732, in do_execute
    cursor.execute(statement, parameters)
sqlite3.IntegrityError: UNIQUE constraint failed: user.username

The above exception was the direct cause of the following exception:

Traceback (most recent call last):
  File "/Users/rjin/OneDrive/MyNotes/a.python/microblog/venv/lib/python3.10/site-packages/flask/app.py", line 2073, in wsgi_app
    response = self.full_dispatch_request()
  File "/Users/rjin/OneDrive/MyNotes/a.python/microblog/venv/lib/python3.10/site-packages/flask/app.py", line 1518, in full_dispatch_request
    rv = self.handle_user_exception(e)
  File "/Users/rjin/OneDrive/MyNotes/a.python/microblog/venv/lib/python3.10/site-packages/flask/app.py", line 1516, in full_dispatch_request
    rv = self.dispatch_request()
  File "/Users/rjin/OneDrive/MyNotes/a.python/microblog/venv/lib/python3.10/site-packages/flask/app.py", line 1502, in dispatch_request
    return self.ensure_sync(self.view_functions[rule.endpoint])(**req.view_args)
  File "/Users/rjin/OneDrive/MyNotes/a.python/microblog/venv/lib/python3.10/site-packages/flask_login/utils.py", line 272, in decorated_view
    return func(*args, **kwargs)
  File "/Users/rjin/OneDrive/MyNotes/a.python/microblog/app/routes.py", line 110, in edit_profile
    db.session.commit()
  File "<string>", line 2, in commit
  File "/Users/rjin/OneDrive/MyNotes/a.python/microblog/venv/lib/python3.10/site-packages/sqlalchemy/orm/session.py", line 1431, in commit
    self._transaction.commit(_to_root=self.future)
  File "/Users/rjin/OneDrive/MyNotes/a.python/microblog/venv/lib/python3.10/site-packages/sqlalchemy/orm/session.py", line 829, in commit
    self._prepare_impl()
  File "/Users/rjin/OneDrive/MyNotes/a.python/microblog/venv/lib/python3.10/site-packages/sqlalchemy/orm/session.py", line 808, in _prepare_impl
    self.session.flush()
  File "/Users/rjin/OneDrive/MyNotes/a.python/microblog/venv/lib/python3.10/site-packages/sqlalchemy/orm/session.py", line 3348, in flush
    self._flush(objects)
  File "/Users/rjin/OneDrive/MyNotes/a.python/microblog/venv/lib/python3.10/site-packages/sqlalchemy/orm/session.py", line 3487, in _flush
    with util.safe_reraise():
  File "/Users/rjin/OneDrive/MyNotes/a.python/microblog/venv/lib/python3.10/site-packages/sqlalchemy/util/langhelpers.py", line 70, in __exit__
    compat.raise_(
  File "/Users/rjin/OneDrive/MyNotes/a.python/microblog/venv/lib/python3.10/site-packages/sqlalchemy/util/compat.py", line 207, in raise_
    raise exception
  File "/Users/rjin/OneDrive/MyNotes/a.python/microblog/venv/lib/python3.10/site-packages/sqlalchemy/orm/session.py", line 3448, in _flush
    flush_context.execute()
  File "/Users/rjin/OneDrive/MyNotes/a.python/microblog/venv/lib/python3.10/site-packages/sqlalchemy/orm/unitofwork.py", line 456, in execute
    rec.execute(self)
  File "/Users/rjin/OneDrive/MyNotes/a.python/microblog/venv/lib/python3.10/site-packages/sqlalchemy/orm/unitofwork.py", line 630, in execute
    util.preloaded.orm_persistence.save_obj(
  File "/Users/rjin/OneDrive/MyNotes/a.python/microblog/venv/lib/python3.10/site-packages/sqlalchemy/orm/persistence.py", line 236, in save_obj
    _emit_update_statements(
  File "/Users/rjin/OneDrive/MyNotes/a.python/microblog/venv/lib/python3.10/site-packages/sqlalchemy/orm/persistence.py", line 1000, in _emit_update_statements
    c = connection._execute_20(
  File "/Users/rjin/OneDrive/MyNotes/a.python/microblog/venv/lib/python3.10/site-packages/sqlalchemy/engine/base.py", line 1614, in _execute_20
    return meth(self, args_10style, kwargs_10style, execution_options)
  File "/Users/rjin/OneDrive/MyNotes/a.python/microblog/venv/lib/python3.10/site-packages/sqlalchemy/sql/elements.py", line 325, in _execute_on_connection
    return connection._execute_clauseelement(
  File "/Users/rjin/OneDrive/MyNotes/a.python/microblog/venv/lib/python3.10/site-packages/sqlalchemy/engine/base.py", line 1481, in _execute_clauseelement
    ret = self._execute_context(
  File "/Users/rjin/OneDrive/MyNotes/a.python/microblog/venv/lib/python3.10/site-packages/sqlalchemy/engine/base.py", line 1845, in _execute_context
    self._handle_dbapi_exception(
  File "/Users/rjin/OneDrive/MyNotes/a.python/microblog/venv/lib/python3.10/site-packages/sqlalchemy/engine/base.py", line 2026, in _handle_dbapi_exception
    util.raise_(
  File "/Users/rjin/OneDrive/MyNotes/a.python/microblog/venv/lib/python3.10/site-packages/sqlalchemy/util/compat.py", line 207, in raise_
    raise exception
  File "/Users/rjin/OneDrive/MyNotes/a.python/microblog/venv/lib/python3.10/site-packages/sqlalchemy/engine/base.py", line 1802, in _execute_context
    self.dialect.do_execute(
  File "/Users/rjin/OneDrive/MyNotes/a.python/microblog/venv/lib/python3.10/site-packages/sqlalchemy/engine/default.py", line 732, in do_execute
    cursor.execute(statement, parameters)
sqlalchemy.exc.IntegrityError: (sqlite3.IntegrityError) UNIQUE constraint failed: user.username
[SQL: UPDATE user SET username=?, about_me=? WHERE user.id = ?]
[parameters: ('susan', "this is xxx, 'Hello!'", 3)]
(Background on this error at: https://sqlalche.me/e/14/gkpj)
2022-01-23 18:04:12,357 INFO: Microblog startup [in /Users/rjin/OneDrive/MyNotes/a.python/microblog/app/__init__.py:33]
2022-01-23 18:04:27,068 ERROR: Exception on /edit_profile [GET] [in /Users/rjin/OneDrive/MyNotes/a.python/microblog/venv/lib/python3.10/site-packages/flask/app.py:1457]
Traceback (most recent call last):
  File "/Users/rjin/OneDrive/MyNotes/a.python/microblog/venv/lib/python3.10/site-packages/flask/app.py", line 2073, in wsgi_app
    response = self.full_dispatch_request()
  File "/Users/rjin/OneDrive/MyNotes/a.python/microblog/venv/lib/python3.10/site-packages/flask/app.py", line 1518, in full_dispatch_request
    rv = self.handle_user_exception(e)
  File "/Users/rjin/OneDrive/MyNotes/a.python/microblog/venv/lib/python3.10/site-packages/flask/app.py", line 1516, in full_dispatch_request
    rv = self.dispatch_request()
  File "/Users/rjin/OneDrive/MyNotes/a.python/microblog/venv/lib/python3.10/site-packages/flask/app.py", line 1502, in dispatch_request
    return self.ensure_sync(self.view_functions[rule.endpoint])(**req.view_args)
  File "/Users/rjin/OneDrive/MyNotes/a.python/microblog/venv/lib/python3.10/site-packages/flask_login/utils.py", line 272, in decorated_view
    return func(*args, **kwargs)
  File "/Users/rjin/OneDrive/MyNotes/a.python/microblog/app/routes.py", line 106, in edit_profile
    form = EditProfileForm()
  File "/Users/rjin/OneDrive/MyNotes/a.python/microblog/venv/lib/python3.10/site-packages/wtforms/form.py", line 208, in __call__
    return type.__call__(cls, *args, **kwargs)
TypeError: EditProfileForm.__init__() missing 1 required positional argument: 'original_username'
2022-01-23 18:06:54,091 INFO: Microblog startup [in /Users/rjin/OneDrive/MyNotes/a.python/microblog/app/__init__.py:33]
2022-01-23 20:12:33,645 INFO: Microblog startup [in /Users/rjin/OneDrive/MyNotes/a.python/python_flask/microblog/app/__init__.py:33]
2022-01-28 16:06:40,962 INFO: Microblog startup [in /Users/rjin/OneDrive/MyNotes/a.python/microblog/app/__init__.py:33]
2022-01-28 16:08:49,898 INFO: Microblog startup [in /Users/rjin/OneDrive/MyNotes/a.python/microblog/app/__init__.py:33]
2022-01-28 16:08:55,602 INFO: Microblog startup [in /Users/rjin/OneDrive/MyNotes/a.python/microblog/app/__init__.py:33]
2022-01-29 13:57:21,185 INFO: Microblog startup [in /Users/rjin/OneDrive/MyNotes/a.python/microblog/app/__init__.py:33]
2022-01-29 14:12:16,047 INFO: Microblog startup [in /Users/rjin/OneDrive/MyNotes/a.python/microblog/app/__init__.py:33]
2022-01-29 18:01:17,966 INFO: Microblog startup [in /Users/rjin/OneDrive/MyNotes/a.python/microblog/app/__init__.py:33]
2022-01-29 18:04:54,271 INFO: Microblog startup [in /Users/rjin/OneDrive/MyNotes/a.python/microblog/app/__init__.py:33]
2022-01-29 18:09:44,087 INFO: Microblog startup [in /Users/rjin/OneDrive/MyNotes/a.python/microblog/app/__init__.py:33]
2022-01-29 18:13:44,735 INFO: Microblog startup [in /Users/rjin/OneDrive/MyNotes/a.python/microblog/app/__init__.py:33]
2022-01-29 18:16:48,937 INFO: Microblog startup [in /Users/rjin/OneDrive/MyNotes/a.python/microblog/app/__init__.py:33]
2022-01-29 18:19:55,359 INFO: Microblog startup [in /Users/rjin/OneDrive/MyNotes/a.python/microblog/app/__init__.py:33]
2022-01-29 18:20:04,797 ERROR: Exception on /app/unarchive_tid [POST] [in /Users/rjin/OneDrive/MyNotes/a.python/microblog/venv/lib/python3.10/site-packages/flask/app.py:1457]
Traceback (most recent call last):
  File "/Users/rjin/OneDrive/MyNotes/a.python/microblog/venv/lib/python3.10/site-packages/flask/app.py", line 2073, in wsgi_app
    response = self.full_dispatch_request()
  File "/Users/rjin/OneDrive/MyNotes/a.python/microblog/venv/lib/python3.10/site-packages/flask/app.py", line 1518, in full_dispatch_request
    rv = self.handle_user_exception(e)
  File "/Users/rjin/OneDrive/MyNotes/a.python/microblog/venv/lib/python3.10/site-packages/flask/app.py", line 1516, in full_dispatch_request
    rv = self.dispatch_request()
  File "/Users/rjin/OneDrive/MyNotes/a.python/microblog/venv/lib/python3.10/site-packages/flask/app.py", line 1502, in dispatch_request
    return self.ensure_sync(self.view_functions[rule.endpoint])(**req.view_args)
  File "/Users/rjin/OneDrive/MyNotes/a.python/microblog/app/routes.py", line 131, in unarchive_tid
    f.write(form.tid)
AttributeError: 'EditTIDForm' object has no attribute 'tid'
2022-01-29 18:20:20,578 INFO: Microblog startup [in /Users/rjin/OneDrive/MyNotes/a.python/microblog/app/__init__.py:33]
