2022-01-30 13:11:49,438 ERROR: Exception on /reset_password/eyJ0eXAiOiJKV1QiLCJhbGciOiJIUzI1NiJ9.eyJyZXNldF9wYXNzd29yZCI6MywiZXhwIjoxNjQzNTIwMDY2LjI3ODM0N30.s7DMxblQ6cks9ov4MlzvuNe75VWShvN_dkuB9bP9KSc [GET] [in /Users/rjin/OneDrive/MyNotes/a.python/microblog/venv/lib/python3.10/site-packages/flask/app.py:1457]
Traceback (most recent call last):
  File "/Users/rjin/OneDrive/MyNotes/a.python/microblog/venv/lib/python3.10/site-packages/flask/app.py", line 2073, in wsgi_app
    response = self.full_dispatch_request()
  File "/Users/rjin/OneDrive/MyNotes/a.python/microblog/venv/lib/python3.10/site-packages/flask/app.py", line 1518, in full_dispatch_request
    rv = self.handle_user_exception(e)
  File "/Users/rjin/OneDrive/MyNotes/a.python/microblog/venv/lib/python3.10/site-packages/flask/app.py", line 1516, in full_dispatch_request
    rv = self.dispatch_request()
  File "/Users/rjin/OneDrive/MyNotes/a.python/microblog/venv/lib/python3.10/site-packages/flask/app.py", line 1502, in dispatch_request
    return self.ensure_sync(self.view_functions[rule.endpoint])(**req.view_args)
  File "/Users/rjin/OneDrive/MyNotes/a.python/microblog/app/routes.py", line 249, in reset_password
    if form.validate_on_submit():
TypeError: FlaskForm.validate_on_submit() missing 1 required positional argument: 'self'
2022-01-30 13:14:50,118 ERROR: Exception on /reset_password/eyJ0eXAiOiJKV1QiLCJhbGciOiJIUzI1NiJ9.eyJyZXNldF9wYXNzd29yZCI6MywiZXhwIjoxNjQzNTIwMDY2LjI3ODM0N30.s7DMxblQ6cks9ov4MlzvuNe75VWShvN_dkuB9bP9KSc [GET] [in /Users/rjin/OneDrive/MyNotes/a.python/microblog/venv/lib/python3.10/site-packages/flask/app.py:1457]
Traceback (most recent call last):
  File "/Users/rjin/OneDrive/MyNotes/a.python/microblog/venv/lib/python3.10/site-packages/flask/app.py", line 2073, in wsgi_app
    response = self.full_dispatch_request()
  File "/Users/rjin/OneDrive/MyNotes/a.python/microblog/venv/lib/python3.10/site-packages/flask/app.py", line 1518, in full_dispatch_request
    rv = self.handle_user_exception(e)
  File "/Users/rjin/OneDrive/MyNotes/a.python/microblog/venv/lib/python3.10/site-packages/flask/app.py", line 1516, in full_dispatch_request
    rv = self.dispatch_request()
  File "/Users/rjin/OneDrive/MyNotes/a.python/microblog/venv/lib/python3.10/site-packages/flask/app.py", line 1502, in dispatch_request
    return self.ensure_sync(self.view_functions[rule.endpoint])(**req.view_args)
  File "/Users/rjin/OneDrive/MyNotes/a.python/microblog/app/routes.py", line 249, in reset_password
    if form.validate_on_submit():
TypeError: FlaskForm.validate_on_submit() missing 1 required positional argument: 'self'
2022-01-30 13:15:16,197 ERROR: Exception on /reset_password/eyJ0eXAiOiJKV1QiLCJhbGciOiJIUzI1NiJ9.eyJyZXNldF9wYXNzd29yZCI6MywiZXhwIjoxNjQzNTIwMzA4LjI3NjY3NH0.DiJUH2SM_eeDJMBNtKO-d6acWLHFeoU_ApzhNI71_kA [GET] [in /Users/rjin/OneDrive/MyNotes/a.python/microblog/venv/lib/python3.10/site-packages/flask/app.py:1457]
Traceback (most recent call last):
  File "/Users/rjin/OneDrive/MyNotes/a.python/microblog/venv/lib/python3.10/site-packages/flask/app.py", line 2073, in wsgi_app
    response = self.full_dispatch_request()
  File "/Users/rjin/OneDrive/MyNotes/a.python/microblog/venv/lib/python3.10/site-packages/flask/app.py", line 1518, in full_dispatch_request
    rv = self.handle_user_exception(e)
  File "/Users/rjin/OneDrive/MyNotes/a.python/microblog/venv/lib/python3.10/site-packages/flask/app.py", line 1516, in full_dispatch_request
    rv = self.dispatch_request()
  File "/Users/rjin/OneDrive/MyNotes/a.python/microblog/venv/lib/python3.10/site-packages/flask/app.py", line 1502, in dispatch_request
    return self.ensure_sync(self.view_functions[rule.endpoint])(**req.view_args)
  File "/Users/rjin/OneDrive/MyNotes/a.python/microblog/app/routes.py", line 249, in reset_password
    if form.validate_on_submit():
TypeError: FlaskForm.validate_on_submit() missing 1 required positional argument: 'self'
2022-01-30 13:18:32,903 INFO: Microblog startup [in /Users/rjin/OneDrive/MyNotes/a.python/microblog/app/__init__.py:36]
2022-01-30 16:20:18,560 INFO: Microblog startup [in /Users/rjin/OneDrive/MyNotes/a.python/microblog/app/__init__.py:36]
2022-01-30 16:23:06,112 INFO: Microblog startup [in /Users/rjin/OneDrive/MyNotes/a.python/microblog/app/__init__.py:36]
2022-01-30 16:27:51,198 INFO: Microblog startup [in /Users/rjin/OneDrive/MyNotes/a.python/microblog/app/__init__.py:36]
2022-01-30 16:29:47,805 INFO: Microblog startup [in /Users/rjin/OneDrive/MyNotes/a.python/microblog/app/__init__.py:36]
2022-01-30 16:30:39,462 INFO: Microblog startup [in /Users/rjin/OneDrive/MyNotes/a.python/microblog/app/__init__.py:36]
2022-01-30 16:32:29,962 INFO: Microblog startup [in /Users/rjin/OneDrive/MyNotes/a.python/microblog/app/__init__.py:36]
2022-01-30 16:32:32,982 ERROR: Exception on /edit_profile [GET] [in /Users/rjin/OneDrive/MyNotes/a.python/microblog/venv/lib/python3.10/site-packages/flask/app.py:1457]
Traceback (most recent call last):
  File "/Users/rjin/OneDrive/MyNotes/a.python/microblog/venv/lib/python3.10/site-packages/flask/app.py", line 2073, in wsgi_app
    response = self.full_dispatch_request()
  File "/Users/rjin/OneDrive/MyNotes/a.python/microblog/venv/lib/python3.10/site-packages/flask/app.py", line 1518, in full_dispatch_request
    rv = self.handle_user_exception(e)
  File "/Users/rjin/OneDrive/MyNotes/a.python/microblog/venv/lib/python3.10/site-packages/flask/app.py", line 1516, in full_dispatch_request
    rv = self.dispatch_request()
  File "/Users/rjin/OneDrive/MyNotes/a.python/microblog/venv/lib/python3.10/site-packages/flask/app.py", line 1502, in dispatch_request
    return self.ensure_sync(self.view_functions[rule.endpoint])(**req.view_args)
  File "/Users/rjin/OneDrive/MyNotes/a.python/microblog/venv/lib/python3.10/site-packages/flask_login/utils.py", line 272, in decorated_view
    return func(*args, **kwargs)
  File "/Users/rjin/OneDrive/MyNotes/a.python/microblog/app/routes.py", line 145, in edit_profile
    return render_template('edit_profile.html', title='Edit Profile', form=form)
  File "/Users/rjin/OneDrive/MyNotes/a.python/microblog/venv/lib/python3.10/site-packages/flask/templating.py", line 147, in render_template
    return _render(
  File "/Users/rjin/OneDrive/MyNotes/a.python/microblog/venv/lib/python3.10/site-packages/flask/templating.py", line 128, in _render
    rv = template.render(context)
  File "/Users/rjin/OneDrive/MyNotes/a.python/microblog/venv/lib/python3.10/site-packages/jinja2/environment.py", line 1291, in render
    self.environment.handle_exception()
  File "/Users/rjin/OneDrive/MyNotes/a.python/microblog/venv/lib/python3.10/site-packages/jinja2/environment.py", line 925, in handle_exception
    raise rewrite_traceback_stack(source=source)
  File "/Users/rjin/OneDrive/MyNotes/a.python/microblog/app/templates/edit_profile.html", line 1, in top-level template code
    {% extends "base.html" %}
  File "/Users/rjin/OneDrive/MyNotes/a.python/microblog/app/templates/base.html", line 33, in top-level template code
    {% block content %}{% endblock %}
  File "/Users/rjin/OneDrive/MyNotes/a.python/microblog/app/templates/edit_profile.html", line 16, in block 'content'
    {{ form.email.label }}<br>
  File "/Users/rjin/OneDrive/MyNotes/a.python/microblog/venv/lib/python3.10/site-packages/jinja2/environment.py", line 474, in getattr
    return getattr(obj, attribute)
jinja2.exceptions.UndefinedError: 'app.forms.EditProfileForm object' has no attribute 'email'
2022-01-30 16:35:33,185 INFO: Microblog startup [in /Users/rjin/OneDrive/MyNotes/a.python/microblog/app/__init__.py:36]
2022-01-30 16:38:12,848 INFO: Microblog startup [in /Users/rjin/OneDrive/MyNotes/a.python/microblog/app/__init__.py:36]
2022-01-30 16:38:27,813 ERROR: Exception on /edit_profile [POST] [in /Users/rjin/OneDrive/MyNotes/a.python/microblog/venv/lib/python3.10/site-packages/flask/app.py:1457]
Traceback (most recent call last):
  File "/Users/rjin/OneDrive/MyNotes/a.python/microblog/venv/lib/python3.10/site-packages/flask/app.py", line 2073, in wsgi_app
    response = self.full_dispatch_request()
  File "/Users/rjin/OneDrive/MyNotes/a.python/microblog/venv/lib/python3.10/site-packages/flask/app.py", line 1518, in full_dispatch_request
    rv = self.handle_user_exception(e)
  File "/Users/rjin/OneDrive/MyNotes/a.python/microblog/venv/lib/python3.10/site-packages/flask/app.py", line 1516, in full_dispatch_request
    rv = self.dispatch_request()
  File "/Users/rjin/OneDrive/MyNotes/a.python/microblog/venv/lib/python3.10/site-packages/flask/app.py", line 1502, in dispatch_request
    return self.ensure_sync(self.view_functions[rule.endpoint])(**req.view_args)
  File "/Users/rjin/OneDrive/MyNotes/a.python/microblog/venv/lib/python3.10/site-packages/flask_login/utils.py", line 272, in decorated_view
    return func(*args, **kwargs)
  File "/Users/rjin/OneDrive/MyNotes/a.python/microblog/app/routes.py", line 134, in edit_profile
    if form.validate_on_submit():
  File "/Users/rjin/OneDrive/MyNotes/a.python/microblog/venv/lib/python3.10/site-packages/flask_wtf/form.py", line 86, in validate_on_submit
    return self.is_submitted() and self.validate()
  File "/Users/rjin/OneDrive/MyNotes/a.python/microblog/venv/lib/python3.10/site-packages/wtforms/form.py", line 329, in validate
    return super().validate(extra)
  File "/Users/rjin/OneDrive/MyNotes/a.python/microblog/venv/lib/python3.10/site-packages/wtforms/form.py", line 146, in validate
    if not field.validate(self, extra):
  File "/Users/rjin/OneDrive/MyNotes/a.python/microblog/venv/lib/python3.10/site-packages/wtforms/fields/core.py", line 242, in validate
    stop_validation = self._run_validation_chain(form, chain)
  File "/Users/rjin/OneDrive/MyNotes/a.python/microblog/venv/lib/python3.10/site-packages/wtforms/fields/core.py", line 262, in _run_validation_chain
    validator(form, self)
  File "/Users/rjin/OneDrive/MyNotes/a.python/microblog/app/forms.py", line 44, in validate_username
    if username.data != self.original_username:
AttributeError: 'EditProfileForm' object has no attribute 'original_username'
